Workbook

Sheet richieste offerte kit+sacc
D1: in giallo prezzo da inserire a listino x codognini
A2: Fornitore | B2: Codice | C2: disegno | D2: descrizione | E2: FINITURA | F2: DESTINAZIONE | G2: lotto field test 50 tende | H2: lotto 200 tende | I2: Lotto produzione a regime 500 tende | J2: € pz lotto field test 50 tende | K2: € pz lotto 200 tende | L2: € pz lotto 500 tende | M2: prezzo da inserire | N2: costo verniciatura | O2: valore alluminio mozzicone | Q2: misura (mm) | R2: peso metro | S2: peso pz | T2: costo totale con ragionamento su lotto acquisto | U2: costo tot se acquistassi tutto per "500 tende". | V2: pz ricavabili con mag presso terxista 18/7 | W2: LT totale (gg da ordine, escluso tutto agosto) | X2: Le configurazioni | Z2: LT totale (gg da ordine, escludere tutto agosto) | AB2: nota prima di ordinare | AE2: confronto prezzo 200pz con lotto da 500
A3: CPA | B3: 090364 | C3: T0002.206A | D3: =VLOOKUP(B3,[1]!Tabella1[[Codice]:[Descrizione]],2,FALSE) -> SUPPORTO CASSONETTO SUPERIORE ZEROGRADI | E3: ANODIZZATO | F3: saccolongo | G3: 30 | H3: 120 | I3: =+G3*10 -> 300 | J3: 13 | K3: 5.22 | L3: 4.16 | M3: =+K3 -> 5.22 | N3: arriva già così | O3: =+S3*4.5 -> 0.4374 | P3: =VLOOKUP(B3,Foglio1!AA:AD,4,FALSE) -> 010608 | Q3: =VLOOKUP(B3,Foglio1!AA:AD,2,FALSE) -> 60 | R3: =VLOOKUP(B3,Foglio1!AA:AE,5,FALSE) -> 1.62 | S3: =+R3*Q3/1000 -> 0.0972 | T3: =+M3*500 -> 2610 | U3: =+L3*500 -> 2080 | V3: =92*13 -> 1196 | W3: 40 | X3: 0050 | Y3: non estrudere per il momento (forse materiale per 2 anni) | Z3: 100 | AB3: =+J3*G3 -> 390 | AC3: =+K3*H3 -> 626.4 | AD3: =+L3*I3 -> 1248 | AE3: =+I3*K3 -> 1566
A4: CPA | B4: 131401 | C4: T0002.452 | D4: =VLOOKUP(B4,[1]!Tabella1[[Codice]:[Descrizione]],2,FALSE) -> BLOCCA MOTORE SUPERIORE | E4: ANODIZZATO | F4: saccolongo | G4: 50 | H4: 200 | I4: =+G4*10 -> 500 | J4: 12 | K4: 7.26 | L4: 6.62 | M4: =+K4 -> 7.26 | N4: arriva già così | O4: =+S4*4.5 -> #N/A | P4: =VLOOKUP(B4,Foglio1!AA:AD,4,FALSE) -> #N/A | Q4: =VLOOKUP(B4,Foglio1!AA:AD,2,FALSE) -> #N/A | R4: =VLOOKUP(B4,Foglio1!AA:AE,5,FALSE) -> #N/A | S4: =+R4*Q4/1000 -> #N/A | T4: =+M4*500 -> 3630 | U4: =+L4*500 -> 3310 | W4: 40 | X4: 0050 | Z4: 40 | AB4: =+J4*G4 -> 600 | AC4: =+K4*H4 -> 1452 | AD4: =+L4*I4 -> 3310 | AE4: =+I4*K4 -> 3630
A5: CPA | B5: 131386 | C5: T0002.411 | D5: =VLOOKUP(B5,[1]!Tabella1[[Codice]:[Descrizione]],2,FALSE) -> PIASTRA ANCORAGGIO GUIDA MENSOLA ANGOLARE ZEROGRADI | E5: GREZZO | F5: veggiano | G5: 120 | H5: 480 | I5: =+G5*10 -> 1200 | J5: 4.08 | K5: 3.25 | L5: 2.93 | M5: =+K5 -> 3.25 | N5: verificare se va verniciata a commessa | O5: =+S5*4.5 -> #N/A | P5: =VLOOKUP(B5,Foglio1!AA:AD,4,FALSE) -> #N/A | Q5: =VLOOKUP(B5,Foglio1!AA:AD,2,FALSE) -> #N/A | R5: =VLOOKUP(B5,Foglio1!AA:AE,5,FALSE) -> #N/A | S5: =+R5*Q5/1000 -> #N/A | T5: =+M5*500 -> 1625 | U5: =+L5*500 -> 1465 | W5: 40 | X5: 0000 + colori mag | Z5: 40 | AB5: =+J5*G5 -> 489.6 | AC5: =+K5*H5 -> 1560 | AD5: =+L5*I5 -> 3516 | AE5: =+I5*K5 -> 3900
A6: CPA | B6: 131388 | C6: T0002.433 | D6: =VLOOKUP(B6,[1]!Tabella1[[Codice]:[Descrizione]],2,FALSE) -> SNODO GAMBA-GUIDA LATO GAMBA ZEROGRADI | E6: GREZZO | F6: veggiano | G6: 20 | H6: 80 | I6: =+G6*10 -> 200 | J6: 55 | K6: 40 | L6: 30 | M6: =+K6 -> 40 | N6: 0.26 | O6: =+S6*4.5 -> #N/A | P6: =VLOOKUP(B6,Foglio1!AA:AD,4,FALSE) -> #N/A | Q6: =VLOOKUP(B6,Foglio1!AA:AD,2,FALSE) -> #N/A | R6: =VLOOKUP(B6,Foglio1!AA:AE,5,FALSE) -> #N/A | S6: =+R6*Q6/1000 -> #N/A | T6: =+M6*500 -> 20000 | U6: =+L6*500 -> 15000 | W6: 40 | X6: 0000 + colori mag | Z6: 40 | AB6: =+J6*G6 -> 1100 | AC6: =+K6*H6 -> 3200 | AD6: =+L6*I6 -> 6000 | AE6: =+I6*K6 -> 8000
A7: CPA | B7: 131389 | C7: T0002.435 | D7: =VLOOKUP(B7,[1]!Tabella1[[Codice]:[Descrizione]],2,FALSE) -> SNODO GAMBA-GUIDA LATO GUIDA ZEROGRADI | E7: GREZZO | F7: veggiano | G7: 20 | H7: 80 | I7: =+G7*10 -> 200 | J7: 35 | K7: 12.14 | L7: 10.26 | M7: =+K7 -> 12.14 | N7: 0.25 | O7: =+S7*4.5 -> #N/A | P7: =VLOOKUP(B7,Foglio1!AA:AD,4,FALSE) -> #N/A | Q7: =VLOOKUP(B7,Foglio1!AA:AD,2,FALSE) -> #N/A | R7: =VLOOKUP(B7,Foglio1!AA:AE,5,FALSE) -> #N/A | S7: =+R7*Q7/1000 -> #N/A | T7: =+M7*500 -> 6070 | U7: =+L7*500 -> 5130 | W7: 40 | X7: 0000 + colori mag | Z7: 40 | AB7: =+J7*G7 -> 700 | AC7: =+K7*H7 -> 971.2 | AD7: =+L7*I7 -> 2052 | AE7: =+I7*K7 -> 2428
A8: CPA | B8: 131390 | C8: T0002.453 | D8: =VLOOKUP(B8,[1]!Tabella1[[Codice]:[Descrizione]],2,FALSE) -> STAFFETTA SUPPORTO TENSIONATORE ZEROGRADI | E8: ANODIZZATO | F8: saccolongo | G8: 75 | H8: 300 | I8: =+G8*10 -> 750 | J8: 10 | K8: 7.22 | L8: 6.57 | M8: =+K8 -> 7.22 | N8: arriva già così | O8: =+S8*4.5 -> #N/A | P8: =VLOOKUP(B8,Foglio1!AA:AD,4,FALSE) -> #N/A | Q8: =VLOOKUP(B8,Foglio1!AA:AD,2,FALSE) -> #N/A | R8: =VLOOKUP(B8,Foglio1!AA:AE,5,FALSE) -> #N/A | S8: =+R8*Q8/1000 -> #N/A | T8: =+M8*500 -> 3610 | U8: =+L8*500 -> 3285 | W8: 40 | X8: 0050 | Z8: 40 | AB8: =+J8*G8 -> 750 | AC8: =+K8*H8 -> 2166 | AD8: =+L8*I8 -> 4927.5 | AE8: =+I8*K8 -> 5415
A9: CPA | B9: 090359 | C9: T0002.246A | D9: =VLOOKUP(B9,[1]!Tabella1[[Codice]:[Descrizione]],2,FALSE) -> AGGANCIO CASSONETTO PARETE ROTABILE LAVORATO ZEROGRADI | E9: ANODIZZATO | F9: veggiano | G9: 16 | H9: 64 | I9: =+G9*10 -> 160 | J9: 17 | K9: 7.73 | L9: 5.15 | M9: =+L9 -> 5.15 | N9: arriva già così | O9: =+S9*4.5 -> 0.463725 | P9: =VLOOKUP(B9,Foglio1!AA:AD,4,FALSE) -> 010629 | Q9: =VLOOKUP(B9,Foglio1!AA:AD,2,FALSE) -> 90 | R9: =VLOOKUP(B9,Foglio1!AA:AE,5,FALSE) -> 1.145 | S9: =+R9*Q9/1000 -> 0.10305 | T9: =+M9*500 -> 2575 | U9: =+L9*500 -> 2575 | V9: =63*5 -> 315 | W9: 40 | X9: 0050 | Y9: non estrudere per il momento (forse materiale per 2 anni) | Z9: 100 | AB9: =+J9*G9 -> 272 | AC9: =+K9*H9 -> 494.72 | AD9: =+L9*I9 -> 824 | AE9: =+I9*K9 -> 1236.8
A10: CPA | B10: 090361 | C10: T0002.217A | D10: =VLOOKUP(B10,[1]!Tabella1[[Codice]:[Descrizione]],2,FALSE) -> ANCORAGGIO GUIDA ZEROGRADI | E10: GREZZO | F10: veggiano | G10: 305 | H10: 1220 | I10: =+G10*10 -> 3050 | J10: 3.64 | K10: 3.36 | L10: 3.24 | M10: =+K10 -> 3.36 | N10: 0.17 | O10: =+S10*4.5 -> 0.18225 | P10: =VLOOKUP(B10,Foglio1!AA:AD,4,FALSE) -> 010617 | Q10: =VLOOKUP(B10,Foglio1!AA:AD,2,FALSE) -> 45 | R10: =VLOOKUP(B10,Foglio1!AA:AE,5,FALSE) -> 0.9 | S10: =+R10*Q10/1000 -> 0.0405 | T10: =+M10*500 -> 1680 | U10: =+L10*500 -> 1620 | V10: =12*120 -> 1440 | W10: 40 | X10: 0000 + colori mag | Y10: estrudi per gennaio | Z10: 100 | AA10: aspetta ad ordinare | AB10: =+J10*G10 -> 1110.2 | AC10: =+K10*H10 -> 4099.2 | AD10: =+L10*I10 -> 9882 | AE10: =+I10*K10 -> 10248
A11: CPA | B11: 090362 | C11: T0002.249A | D11: =VLOOKUP(B11,[1]!Tabella1[[Codice]:[Descrizione]],2,FALSE) -> ANTI SOLLEVAMENTO SUPPORTO PARETE ROTABILE LAVORATO ZEROGRADI | E11: ANODIZZATO | F11: veggiano | G11: 16 | H11: 64 | I11: =+G11*10 -> 160 | J11: 17 | K11: 5.34 | L11: 3.4 | M11: =+L11 -> 3.4 | N11: arriva già così | O11: =+S11*4.5 -> 0.226395 | P11: =VLOOKUP(B11,Foglio1!AA:AD,4,FALSE) -> 010637 | Q11: =VLOOKUP(B11,Foglio1!AA:AD,2,FALSE) -> 90 | R11: =VLOOKUP(B11,Foglio1!AA:AE,5,FALSE) -> 0.559 | S11: =+R11*Q11/1000 -> 0.05031 | T11: =+M11*500 -> 1700 | U11: =+L11*500 -> 1700 | V11: =63*11 -> 693 | W11: 40 | X11: 0050 | Y11: non estrudere per il momento (forse materiale per 2 anni) | Z11: 100 | AB11: =+J11*G11 -> 272 | AC11: =+K11*H11 -> 341.76 | AD11: =+L11*I11 -> 544 | AE11: =+I11*K11 -> 854.4
A12: CPA | B12: 090363 | C12: T0002.220A | D12: =VLOOKUP(B12,[1]!Tabella1[[Codice]:[Descrizione]],2,FALSE) -> SUPPORTINO TETTUCCIO LAVORATO ZEROGRADI | E12: ANODIZZATO | F12: veggiano | G12: 15 | H12: 60 | I12: =+G12*10 -> 150 | J12: 17 | K12: 5.52 | L12: 3.7 | M12: =+L12 -> 3.7 | N12: arriva già così | O12: =+S12*4.5 -> 0.128304 | P12: =VLOOKUP(B12,Foglio1!AA:AD,4,FALSE) -> 010619 | Q12: =VLOOKUP(B12,Foglio1!AA:AD,2,FALSE) -> 32 | R12: =VLOOKUP(B12,Foglio1!AA:AE,5,FALSE) -> 0.891 | S12: =+R12*Q12/1000 -> 0.028512 | T12: =+M12*500 -> 1850 | U12: =+L12*500 -> 1850 | V12: =162*5 -> 810 | W12: 40 | X12: 0050 | Y12: non estrudere per il momento (forse materiale per 2 anni) | Z12: 100 | AB12: =+J12*G12 -> 255 | AC12: =+K12*H12 -> 331.2 | AD12: =+L12*I12 -> 555 | AE12: =+I12*K12 -> 828
A13: CPA | B13: 090365 | C13: T0002.245A | D13: =VLOOKUP(B13,[1]!Tabella1[[Codice]:[Descrizione]],2,FALSE) -> SUPPORTO PARETE ANCORABILE ROTABILE LAVORATO ZEROGRADI | E13: ANODIZZATO | F13: veggiano | G13: 16 | H13: 64 | I13: =+G13*10 -> 160 | J13: 25 | K13: 12.1 | L13: 9.75 | M13: =+L13 -> 9.75 | N13: arriva già così | O13: =+S13*4.5 -> 4.32378 | P13: =VLOOKUP(B13,Foglio1!AA:AD,4,FALSE) -> 010639 | Q13: =VLOOKUP(B13,Foglio1!AA:AD,2,FALSE) -> 180 | R13: =VLOOKUP(B13,Foglio1!AA:AE,5,FALSE) -> 5.338 | S13: =+R13*Q13/1000 -> 0.96084 | T13: =+M13*500 -> 4875 | U13: =+L13*500 -> 4875 | V13: =32*7 -> 224 | W13: 40 | X13: 0050 | Y13: estrudi per gennaio | Z13: 100 | AB13: =+J13*G13 -> 400 | AC13: =+K13*H13 -> 774.4 | AD13: =+L13*I13 -> 1560 | AE13: =+I13*K13 -> 1936
A14: CPA | B14: 131374 | C14: T0002.232A | D14: =VLOOKUP(B14,[1]!Tabella1[[Codice]:[Descrizione]],2,FALSE) -> ANCORAMENTO TETTUCCIO SUPPORTO PARETE ZEROGRADI | E14: ANODIZZATO | F14: veggiano | G14: 10 | H14: 40 | I14: =+G14*10 -> 100 | J14: 27 | K14: 12.1 | L14: 8.7 | M14: =+L14 -> 8.7 | N14: 0.25 | O14: =+S14*4.5 -> #N/A | P14: =VLOOKUP(B14,Foglio1!AA:AD,4,FALSE) -> #N/A | Q14: =VLOOKUP(B14,Foglio1!AA:AD,2,FALSE) -> #N/A | R14: =VLOOKUP(B14,Foglio1!AA:AE,5,FALSE) -> #N/A | S14: =+R14*Q14/1000 -> #N/A | T14: =+M14*500 -> 4350 | U14: =+L14*500 -> 4350 | W14: 40 | X14: 0050 | Z14: 40 | AB14: =+J14*G14 -> 270 | AC14: =+K14*H14 -> 484 | AD14: =+L14*I14 -> 870 | AE14: =+I14*K14 -> 1210
A15: CPA | B15: 131375 | C15: T0002.417 | D15: =VLOOKUP(B15,[1]!Tabella1[[Codice]:[Descrizione]],2,FALSE) -> BASAMENTO RINVIO ANGOLARE GAMBA TELESCOPICA ZEROGRADI | E15: GREZZO | F15: veggiano | G15: 3 | H15: 12 | I15: =+G15*10 -> 30 | J15: 50 | K15: 25 | L15: 18 | M15: =+L15 -> 18 | N15: resta gz | O15: =+S15*4.5 -> #N/A | P15: =VLOOKUP(B15,Foglio1!AA:AD,4,FALSE) -> #N/A | Q15: =VLOOKUP(B15,Foglio1!AA:AD,2,FALSE) -> #N/A | R15: =VLOOKUP(B15,Foglio1!AA:AE,5,FALSE) -> #N/A | S15: =+R15*Q15/1000 -> #N/A | T15: =+M15*500 -> 9000 | U15: =+L15*500 -> 9000 | W15: 40 | X15: 0000 | Z15: 40 | AB15: =+J15*G15 -> 150 | AC15: =+K15*H15 -> 300 | AD15: =+L15*I15 -> 540 | AE15: =+I15*K15 -> 750
A16: CPA | B16: 131377 | C16: T0002.426 | D16: =VLOOKUP(B16,[1]!Tabella1[[Codice]:[Descrizione]],2,FALSE) -> DISCO FINECORSA GAMBA TELESCOPICA ZEROGRADI | E16: GREZZO | F16: veggiano | G16: 3 | H16: 12 | I16: =+G16*10 -> 30 | J16: 35 | K16: 30 | L16: 20 | M16: =+L16 -> 20 | N16: resta gz | O16: =+S16*4.5 -> #N/A | P16: =VLOOKUP(B16,Foglio1!AA:AD,4,FALSE) -> #N/A | Q16: =VLOOKUP(B16,Foglio1!AA:AD,2,FALSE) -> #N/A | R16: =VLOOKUP(B16,Foglio1!AA:AE,5,FALSE) -> #N/A | S16: =+R16*Q16/1000 -> #N/A | T16: =+M16*500 -> 10000 | U16: =+L16*500 -> 10000 | W16: 40 | X16: 0000 | Z16: 40 | AB16: =+J16*G16 -> 105 | AC16: =+K16*H16 -> 360 | AD16: =+L16*I16 -> 600 | AE16: =+I16*K16 -> 900
A17: CPA | B17: 131391 | C17: T0002.431 | D17: =VLOOKUP(B17,[1]!Tabella1[[Codice]:[Descrizione]],2,FALSE) -> SUPPORTO FRANGITRATTA STATICO ZEROGRADI | E17: ANODIZZATO | F17: veggiano | G17: 90 | H17: 360 | I17: =+G17*10 -> 900 | J17: 12 | K17: 9.32 | L17: 8.16 | M17: =+K17 -> 9.32 | N17: non c'è a sistema | O17: =+S17*4.5 -> #N/A | P17: =VLOOKUP(B17,Foglio1!AA:AD,4,FALSE) -> #N/A | Q17: =VLOOKUP(B17,Foglio1!AA:AD,2,FALSE) -> #N/A | R17: =VLOOKUP(B17,Foglio1!AA:AE,5,FALSE) -> #N/A | S17: =+R17*Q17/1000 -> #N/A | T17: =+M17*500 -> 4660 | U17: =+L17*500 -> 4080 | W17: 40 | X17: 0050 | Z17: 40 | AB17: =+J17*G17 -> 1080 | AC17: =+K17*H17 -> 3355.2 | AD17: =+L17*I17 -> 7344 | AE17: =+I17*K17 -> 8388
A18: CPA | B18: 131403 | C18: T0002.455S | D18: =VLOOKUP(B18,[1]!Tabella1[[Codice]:[Descrizione]],2,FALSE) -> TAPPO CASSONETTO VOLANT DX | E18: GREZZO | F18: veggiano | G18: 15 | H18: 60 | I18: =+G18*10 -> 150 | J18: 60 | K18: 40 | L18: 26 | M18: =+K18 -> 40 | N18: a commessa-non ho il costo | O18: =+S18*4.5 -> #N/A | P18: =VLOOKUP(B18,Foglio1!AA:AD,4,FALSE) -> #N/A | Q18: =VLOOKUP(B18,Foglio1!AA:AD,2,FALSE) -> #N/A | R18: =VLOOKUP(B18,Foglio1!AA:AE,5,FALSE) -> #N/A | S18: =+R18*Q18/1000 -> #N/A | T18: =+M18*500 -> 20000 | U18: =+L18*500 -> 13000 | W18: 40 | X18: 0000 + colori mag | Z18: 40 | AB18: =+J18*G18 -> 900 | AC18: =+K18*H18 -> 2400 | AD18: =+L18*I18 -> 3900 | AE18: =+I18*K18 -> 6000
A19: CPA | B19: 131404 | C19: T0002.455 | D19: =VLOOKUP(B19,[1]!Tabella1[[Codice]:[Descrizione]],2,FALSE) -> TAPPO CASSONETTO VOLANT SX | E19: GREZZO | F19: veggiano | G19: 15 | H19: 60 | I19: =+G19*10 -> 150 | J19: 60 | K19: 40 | L19: 26 | M19: =+K19 -> 40 | N19: a commessa-non ho il costo | O19: =+S19*4.5 -> #N/A | P19: =VLOOKUP(B19,Foglio1!AA:AD,4,FALSE) -> #N/A | Q19: =VLOOKUP(B19,Foglio1!AA:AD,2,FALSE) -> #N/A | R19: =VLOOKUP(B19,Foglio1!AA:AE,5,FALSE) -> #N/A | S19: =+R19*Q19/1000 -> #N/A | T19: =+M19*500 -> 20000 | U19: =+L19*500 -> 13000 | W19: 40 | X19: 0000 + colori mag | Z19: 40 | AB19: =+J19*G19 -> 900 | AC19: =+K19*H19 -> 2400 | AD19: =+L19*I19 -> 3900 | AE19: =+I19*K19 -> 6000
A20: CPA | B20: 131405 | C20: T0002.456 | D20: =VLOOKUP(B20,[1]!Tabella1[[Codice]:[Descrizione]],2,FALSE) -> PIN COLLEGAMENTO VOLANT LAVORATO | E20: ANODIZZATO | F20: veggiano | G20: 15 | H20: 60 | I20: =+G20*10 -> 150 | J20: 16 | K20: 7.96 | L20: 6.4 | M20: =+K20 -> 7.96 | N20: arriva già così | O20: =+S20*4.5 -> #N/A | P20: =VLOOKUP(B20,Foglio1!AA:AD,4,FALSE) -> #N/A | Q20: =VLOOKUP(B20,Foglio1!AA:AD,2,FALSE) -> #N/A | R20: =VLOOKUP(B20,Foglio1!AA:AE,5,FALSE) -> #N/A | S20: =+R20*Q20/1000 -> #N/A | T20: =+M20*500 -> 3980 | U20: =+L20*500 -> 3200 | W20: 40 | X20: 0050 | Z20: 40 | AB20: =+J20*G20 -> 240 | AC20: =+K20*H20 -> 477.6 | AD20: =+L20*I20 -> 960 | AE20: =+I20*K20 -> 1194
A21: CPA | B21: 131406 | C21: T0002.457 | D21: =VLOOKUP(B21,[1]!Tabella1[[Codice]:[Descrizione]],2,FALSE) -> SUPPORTO INTERMEDIO TETTUCCIO | E21: ANODIZZATO | F21: veggiano | G21: 5 | H21: 20 | I21: =+G21*10 -> 50 | J21: 35 | K21: 19 | L21: 11 | M21: 11 | N21: arriva già così | O21: =+S21*4.5 -> #N/A | P21: =VLOOKUP(B21,Foglio1!AA:AD,4,FALSE) -> #N/A | Q21: =VLOOKUP(B21,Foglio1!AA:AD,2,FALSE) -> #N/A | R21: =VLOOKUP(B21,Foglio1!AA:AE,5,FALSE) -> #N/A | S21: =+R21*Q21/1000 -> #N/A | W21: 40 | X21: 0050 | Z21: 40 | AB21: =+J21*G21 -> 175 | AC21: =+K21*H21 -> 380 | AD21: =+L21*I21 -> 550 | AE21: =+I21*K21 -> 950
Q22: =VLOOKUP(B22,Foglio1!AA:AD,2,FALSE) -> #N/A | R22: =VLOOKUP(B22,Foglio1!AA:AE,5,FALSE) -> #N/A | AB22: =SUM(AB3:AB21) -> 10158.8 | AC22: =SUM(AC3:AC21) -> 26173.68 | AD22: =SUM(AD3:AD21) -> 53082.5 | AE22: =+I22*K22 -> 0
Q23: =VLOOKUP(B23,Foglio1!AA:AD,2,FALSE) -> #N/A | R23: =VLOOKUP(B23,Foglio1!AA:AE,5,FALSE) -> #N/A | AB23: =+AB22/50 -> 203.176 | AC23: =+AC22/200 -> 130.8684 | AD23: =+AD22/500 -> 106.165 | AE23: =+I23*K23 -> 0
B24: 5 | J24: procedere col verde | Q24: =VLOOKUP(B24,Foglio1!AA:AD,2,FALSE) -> #N/A | R24: =VLOOKUP(B24,Foglio1!AA:AE,5,FALSE) -> #N/A | AD24: 1 | AU24: 0 | BI24: 3
A25: Fornitore | B25: Codice | C25: disegno | D25: =VLOOKUP(B25,[1]!Tabella1[[Codice]:[Descrizione]],2,FALSE) -> #N/A | E25: colore | F25: DESTINAZIONE | G25: lotto field test | H25: lotto 200 moduli | I25: Lotto produzione a regime 500 moduli | J25: € pz lotto field test | K25: € pz lotto 200 moduli | L25: € pz lotto 500 moduli | Q25: =VLOOKUP(B25,Foglio1!AA:AD,2,FALSE) -> #N/A | R25: =VLOOKUP(B25,Foglio1!AA:AE,5,FALSE) -> #N/A | W25: LT totale (gg da ordine, escluso tutto agosto) | Z25: LT totale (gg da ordine, escludere tutto agosto)
A26: 4C | B26: 111459 | C26: 3GE40.005 | D26: =VLOOKUP(B26,[1]!Tabella1[[Codice]:[Descrizione]],2,FALSE) -> ROTELLA TERMINALE ANTI SCAVALLAMENTO ZEROGRADI | E26: P073 | F26: VEGGIANO | G26: 100 | H26: =+G26*4 -> 400 | I26: =+G26*10 -> 1000 | J26: 0.55 | K26: 0.44 | L26: 0.36 | M26: =+L26 -> 0.36 | Q26: =VLOOKUP(B26,Foglio1!AA:AD,2,FALSE) -> #N/A | R26: =VLOOKUP(B26,Foglio1!AA:AE,5,FALSE) -> #N/A | T26: =+M26*500 -> 180 | U26: =+L26*500 -> 180 | W26: 35 | Z26: 40 | AB26: =+J26*G26 -> 55 | AC26: =+K26*H26 -> 176 | AD26: =+L26*I26 -> 360
A27: 4C | B27: 111460 | C27: T0002.137 | D27: =VLOOKUP(B27,[1]!Tabella1[[Codice]:[Descrizione]],2,FALSE) -> AVVOLGICINGHIA CHIUSURA LATO FOLLE ZEROGRADI | E27: P073 | F27: VEGGIANO | G27: 50 | H27: =+G27*4 -> 200 | I27: =+G27*10 -> 500 | J27: 1.2 | K27: 0.94 | L27: 0.74 | M27: =+L27 -> 0.74 | Q27: =VLOOKUP(B27,Foglio1!AA:AD,2,FALSE) -> #N/A | R27: =VLOOKUP(B27,Foglio1!AA:AE,5,FALSE) -> #N/A | T27: =+M27*500 -> 370 | U27: =+L27*500 -> 370 | W27: 35 | Z27: 40 | AB27: =+J27*G27 -> 60 | AC27: =+K27*H27 -> 188 | AD27: =+L27*I27 -> 370
A28: 4C | B28: 111461 | C28: T0002.138 | D28: =VLOOKUP(B28,[1]!Tabella1[[Codice]:[Descrizione]],2,FALSE) -> AVVOLGICINGHIA CHIUSURA LATO MOTORE ZEROGRADI | E28: P073 | F28: VEGGIANO | G28: 50 | H28: =+G28*4 -> 200 | I28: =+G28*10 -> 500 | J28: 0.73 | K28: 0.61 | L28: 0.51 | M28: =+L28 -> 0.51 | Q28: =VLOOKUP(B28,Foglio1!AA:AD,2,FALSE) -> #N/A | R28: =VLOOKUP(B28,Foglio1!AA:AE,5,FALSE) -> #N/A | T28: =+M28*500 -> 255 | U28: =+L28*500 -> 255 | W28: 35 | Z28: 40 | AB28: =+J28*G28 -> 36.5 | AC28: =+K28*H28 -> 122 | AD28: =+L28*I28 -> 255
A29: 4C | B29: 111462 | C29: T0002.136 | D29: =VLOOKUP(B29,[1]!Tabella1[[Codice]:[Descrizione]],2,FALSE) -> AVVOLGICINGHIA CORONA ESTERNA ZEROGRADI | E29: P073 | F29: VEGGIANO | G29: 100 | H29: =+G29*4 -> 400 | I29: =+G29*10 -> 1000 | J29: 1.56 | K29: 1.27 | L29: 1.08 | M29: =+L29 -> 1.08 | Q29: =VLOOKUP(B29,Foglio1!AA:AD,2,FALSE) -> #N/A | R29: =VLOOKUP(B29,Foglio1!AA:AE,5,FALSE) -> #N/A | T29: =+M29*500 -> 540 | U29: =+L29*500 -> 540 | W29: 35 | Z29: 40 | AB29: =+J29*G29 -> 156 | AC29: =+K29*H29 -> 508 | AD29: =+L29*I29 -> 1080
A30: 4C | B30: 111463 | C30: T0002.135 | D30: =VLOOKUP(B30,[1]!Tabella1[[Codice]:[Descrizione]],2,FALSE) -> AVVOLGICINGHIA SEMISUPPORTO PRINCIPALE ZEROGRADI | E30: P073 | F30: VEGGIANO | G30: 200 | H30: =+G30*4 -> 800 | I30: =+G30*10 -> 2000 | J30: 0.76 | K30: 0.64 | L30: 0.53 | M30: =+L30 -> 0.53 | Q30: =VLOOKUP(B30,Foglio1!AA:AD,2,FALSE) -> #N/A | R30: =VLOOKUP(B30,Foglio1!AA:AE,5,FALSE) -> #N/A | T30: =+M30*500 -> 265 | U30: =+L30*500 -> 265 | W30: 35 | Z30: 40 | AB30: =+J30*G30 -> 152 | AC30: =+K30*H30 -> 512 | AD30: =+L30*I30 -> 1060
A31: 4C | B31: 111464 | C31: T0002.115 | D31: =VLOOKUP(B31,[1]!Tabella1[[Codice]:[Descrizione]],2,FALSE) -> GUSCIO SUPPORTO MOLLA LATO INTERNO ZEROGRADI | E31: P073 | F31: VEGGIANO | G31: 100 | H31: =+G31*4 -> 400 | I31: =+G31*10 -> 1000 | J31: 0.9 | K31: 0.79 | L31: 0.68 | M31: =+L31 -> 0.68 | Q31: =VLOOKUP(B31,Foglio1!AA:AD,2,FALSE) -> #N/A | R31: =VLOOKUP(B31,Foglio1!AA:AE,5,FALSE) -> #N/A | T31: =+M31*500 -> 340 | U31: =+L31*500 -> 340 | W31: 35 | Z31: 40 | AB31: =+J31*G31 -> 90 | AC31: =+K31*H31 -> 316 | AD31: =+L31*I31 -> 680
A32: 4C | B32: 111465 | C32: T0002.141 | D32: =VLOOKUP(B32,[1]!Tabella1[[Codice]:[Descrizione]],2,FALSE) -> PROTEGGI TELO FRANGITRATTA ZEROGRADI | E32: P134 | F32: SACCOLONGO | G32: 180 | H32: =+G32*4 -> 720 | I32: =+G32*10 -> 1800 | J32: 0.46 | K32: 0.37 | L32: 0.32 | M32: =+L32 -> 0.32 | Q32: =VLOOKUP(B32,Foglio1!AA:AD,2,FALSE) -> #N/A | R32: =VLOOKUP(B32,Foglio1!AA:AE,5,FALSE) -> #N/A | T32: =+M32*500 -> 160 | U32: =+L32*500 -> 160 | W32: 35 | Z32: 40 | AB32: =+J32*G32 -> 82.8 | AC32: =+K32*H32 -> 266.4 | AD32: =+L32*I32 -> 576
A33: 4C | B33: 111466 | C33: T0002.129 | D33: =VLOOKUP(B33,[1]!Tabella1[[Codice]:[Descrizione]],2,FALSE) -> ROTELLA CARRELLO-RINVIO ZEROGRADI | E33: P073 | F33: VEGGIANO | G33: 460 | H33: =+G33*4 -> 1840 | I33: =+G33*10 -> 4600 | J33: 0.22 | K33: 0.18 | L33: 0.15 | M33: =+L33 -> 0.15 | Q33: =VLOOKUP(B33,Foglio1!AA:AD,2,FALSE) -> #N/A | R33: =VLOOKUP(B33,Foglio1!AA:AE,5,FALSE) -> #N/A | T33: =+M33*500 -> 75 | U33: =+L33*500 -> 75 | W33: 35 | Z33: 40 | AB33: =+J33*G33 -> 101.2 | AC33: =+K33*H33 -> 331.2 | AD33: =+L33*I33 -> 690
A34: 4C | B34: 111467 | C34: T0002.150 | D34: =VLOOKUP(B34,[1]!Tabella1[[Codice]:[Descrizione]],2,FALSE) -> TAPPINO ANCORAGGIO GUIDA ZEROGRADI | E34: P134 | F34: VEGGIANO | G34: 430 | H34: =+G34*4 -> 1720 | I34: =+G34*10 -> 4300 | J34: 0.24 | K34: 0.19 | L34: 0.16 | M34: =+L34 -> 0.16 | Q34: =VLOOKUP(B34,Foglio1!AA:AD,2,FALSE) -> #N/A | R34: =VLOOKUP(B34,Foglio1!AA:AE,5,FALSE) -> #N/A | T34: =+M34*500 -> 80 | U34: =+L34*500 -> 80 | W34: 35 | Z34: 40 | AB34: =+J34*G34 -> 103.2 | AC34: =+K34*H34 -> 326.8 | AD34: =+L34*I34 -> 688
A35: 4C | B35: 111468 | C35: T0002.133 | D35: =VLOOKUP(B35,[1]!Tabella1[[Codice]:[Descrizione]],2,FALSE) -> TAPPO CHIUSURA SUPERIORE GAMBA TELESCOPICA ZEROGRADI | E35: P134 | F35: SACCOLONGO | G35: 50 | H35: 50 | I35: 100 | J35: 1.75 | K35: 1.75 | L35: 1.45 | M35: =+L35 -> 1.45 | Q35: =VLOOKUP(B35,Foglio1!AA:AD,2,FALSE) -> #N/A | R35: =VLOOKUP(B35,Foglio1!AA:AE,5,FALSE) -> #N/A | T35: =+M35*500 -> 725 | U35: =+L35*500 -> 725 | W35: 35 | Z35: 40 | AB35: =+J35*G35 -> 87.5 | AC35: =+K35*H35 -> 87.5 | AD35: =+L35*I35 -> 145
A36: 4C | B36: 111468 | C36: T0002.133 | D36: =VLOOKUP(B36,[1]!Tabella1[[Codice]:[Descrizione]],2,FALSE) -> TAPPO CHIUSURA SUPERIORE GAMBA TELESCOPICA ZEROGRADI | E36: P073 | F36: SACCOLONGO | G36: 50 | H36: 50 | I36: 100 | J36: 1.75 | K36: 1.75 | L36: 1.45 | M36: =+L36 -> 1.45 | Q36: =VLOOKUP(B36,Foglio1!AA:AD,2,FALSE) -> #N/A | R36: =VLOOKUP(B36,Foglio1!AA:AE,5,FALSE) -> #N/A | T36: =+M36*500 -> 725 | U36: =+L36*500 -> 725 | W36: 35 | Z36: 40 | AB36: =+J36*G36 -> 87.5 | AC36: =+K36*H36 -> 87.5 | AD36: =+L36*I36 -> 145
A37: 4C | B37: 111468 | C37: T0002.133 | D37: =VLOOKUP(B37,[1]!Tabella1[[Codice]:[Descrizione]],2,FALSE) -> TAPPO CHIUSURA SUPERIORE GAMBA TELESCOPICA ZEROGRADI | E37: P053 | F37: SACCOLONGO | G37: 50 | H37: 50 | I37: 100 | J37: 1.75 | K37: 1.75 | L37: 1.45 | M37: =+L37 -> 1.45 | Q37: =VLOOKUP(B37,Foglio1!AA:AD,2,FALSE) -> #N/A | R37: =VLOOKUP(B37,Foglio1!AA:AE,5,FALSE) -> #N/A | T37: =+M37*500 -> 725 | U37: =+L37*500 -> 725 | W37: 35 | Z37: 40 | AB37: =+J37*G37 -> 87.5 | AC37: =+K37*H37 -> 87.5 | AD37: =+L37*I37 -> 145
A38: 4C | B38: 111470 | C38: T0002.139 | D38: =VLOOKUP(B38,[1]!Tabella1[[Codice]:[Descrizione]],2,FALSE) -> TRASCINATORE MOLLA ESTREMO Ø85 ZEROGRADI | E38: P073 | F38: VEGGIANO | G38: 100 | H38: =+G38*4 -> 400 | I38: =+G38*10 -> 1000 | J38: 1.21 | K38: 0.97 | L38: 0.9 | M38: =+L38 -> 0.9 | Q38: =VLOOKUP(B38,Foglio1!AA:AD,2,FALSE) -> #N/A | R38: =VLOOKUP(B38,Foglio1!AA:AE,5,FALSE) -> #N/A | T38: =+M38*500 -> 450 | U38: =+L38*500 -> 450 | W38: 35 | Z38: 40 | AB38: =+J38*G38 -> 121 | AC38: =+K38*H38 -> 388 | AD38: =+L38*I38 -> 900
A39: 4C | B39: 111471 | C39: T0002.112 | D39: =VLOOKUP(B39,[1]!Tabella1[[Codice]:[Descrizione]],2,FALSE) -> TRASCINATORE MOTORE MOLLA BASE ZEROGRADI | E39: P073 | F39: VEGGIANO | G39: 100 | H39: =+G39*4 -> 400 | I39: =+G39*10 -> 1000 | J39: 0.94 | K39: 0.84 | L39: 0.76 | M39: =+L39 -> 0.76 | Q39: =VLOOKUP(B39,Foglio1!AA:AD,2,FALSE) -> #N/A | R39: =VLOOKUP(B39,Foglio1!AA:AE,5,FALSE) -> #N/A | T39: =+M39*500 -> 380 | U39: =+L39*500 -> 380 | W39: 35 | Z39: 40 | AB39: =+J39*G39 -> 94 | AC39: =+K39*H39 -> 336 | AD39: =+L39*I39 -> 760
A40: 4C | B40: 111472 | C40: T0002.119 | D40: =VLOOKUP(B40,[1]!Tabella1[[Codice]:[Descrizione]],2,FALSE) -> TRASCINATORE MOTORE MOLLA CHERUBINI P/ZEROGRADI | E40: P073 | F40: SACCOLONGO | G40: 50 | H40: 50 | I40: 100 | J40: 1.5 | K40: 1.5 | L40: 1.25 | M40: =+L40 -> 1.25 | Q40: =VLOOKUP(B40,Foglio1!AA:AD,2,FALSE) -> #N/A | R40: =VLOOKUP(B40,Foglio1!AA:AE,5,FALSE) -> #N/A | T40: =+M40*500 -> 625 | U40: =+L40*500 -> 625 | W40: 35 | Z40: 40 | AB40: =+J40*G40 -> 75 | AC40: =+K40*H40 -> 75 | AD40: =+L40*I40 -> 125
...

Sheet Foglio2
D1: in giallo prezzo da inserire a listino x codognini
A2: Fornitore | B2: Codice | C2: disegno | D2: descrizione | E2: FINITURA | F2: prezzo da inserire a listino forn | G2: costo verniciatura | H2: valore alluminio mozzicone | I2: profilo da cui si ricava | J2: misura (mm) | K2: peso metro | L2: peso pz | M2: Le configurazioni | N2: costo totale articolo
A3: CPA | B3: 090364 | C3: T0002.206A | D3: SUPPORTO CASSONETTO SUPERIORE ZEROGRADI | E3: ANODIZZATO | F3: 5.22 | G3: arriva già così | H3: 0.4374 | I3: 010608 | J3: 60 | K3: 1.62 | L3: 0.0972 | M3: 0050 | N3: =+F3+H3 -> 5.6574
A4: CPA | B4: 131401 | C4: T0002.452 | D4: BLOCCA MOTORE SUPERIORE | E4: ANODIZZATO | F4: 7.26 | G4: arriva già così | H4: #N/A | I4: #N/A | J4: #N/A | K4: #N/A | L4: #N/A | M4: 0050
A5: CPA | B5: 131386 | C5: T0002.411 | D5: PIASTRA ANCORAGGIO GUIDA MENSOLA ANGOLARE ZEROGRADI | E5: GREZZO | F5: 3.25 | G5: verificare se va verniciata a commessa | H5: #N/A | I5: #N/A | J5: #N/A | K5: #N/A | L5: #N/A | M5: 0000 + colori mag
A6: CPA | B6: 131388 | C6: T0002.433 | D6: SNODO GAMBA-GUIDA LATO GAMBA ZEROGRADI | E6: GREZZO | F6: 40 | G6: 0.26 | H6: #N/A | I6: #N/A | J6: #N/A | K6: #N/A | L6: #N/A | M6: 0000 + colori mag | N6: =+F6+G6 -> 40.26
A7: CPA | B7: 131389 | C7: T0002.435 | D7: SNODO GAMBA-GUIDA LATO GUIDA ZEROGRADI | E7: GREZZO | F7: 12.14 | G7: 0.25 | H7: #N/A | I7: #N/A | J7: #N/A | K7: #N/A | L7: #N/A | M7: 0000 + colori mag | N7: =+F7+G7 -> 12.39
A8: CPA | B8: 131390 | C8: T0002.453 | D8: STAFFETTA SUPPORTO TENSIONATORE ZEROGRADI | E8: ANODIZZATO | F8: 7.22 | G8: arriva già così | H8: #N/A | I8: #N/A | J8: #N/A | K8: #N/A | L8: #N/A | M8: 0050
A9: CPA | B9: 090359 | C9: T0002.246A | D9: AGGANCIO CASSONETTO PARETE ROTABILE LAVORATO ZEROGRADI | E9: ANODIZZATO | F9: 5.15 | G9: arriva già così | H9: 0.463725 | I9: 010629 | J9: 90 | K9: 1.145 | L9: 0.10305 | M9: 0050
A10: CPA | B10: 090361 | C10: T0002.217A | D10: ANCORAGGIO GUIDA ZEROGRADI | E10: GREZZO | F10: 3.36 | G10: 0.17 | H10: 0.18225 | I10: 010617 | J10: 45 | K10: 0.9 | L10: 0.0405 | M10: 0000 + colori mag | N10: =+F10+G10+H10 -> 3.71225
A11: CPA | B11: 090362 | C11: T0002.249A | D11: ANTI SOLLEVAMENTO SUPPORTO PARETE ROTABILE LAVORATO ZEROGRADI | E11: ANODIZZATO | F11: 3.4 | G11: arriva già così | H11: 0.226395 | I11: 010637 | J11: 90 | K11: 0.559 | L11: 0.05031 | M11: 0050
A12: CPA | B12: 090363 | C12: T0002.220A | D12: SUPPORTINO TETTUCCIO LAVORATO ZEROGRADI | E12: ANODIZZATO | F12: 3.7 | G12: arriva già così | H12: 0.128304 | I12: 010619 | J12: 32 | K12: 0.891 | L12: 0.028512 | M12: 0050
A13: CPA | B13: 090365 | C13: T0002.245A | D13: SUPPORTO PARETE ANCORABILE ROTABILE LAVORATO ZEROGRADI | E13: ANODIZZATO | F13: 9.75 | G13: arriva già così | H13: 4.32378 | I13: 010639 | J13: 180 | K13: 5.338 | L13: 0.96084 | M13: 0050
A14: CPA | B14: 131374 | C14: T0002.232A | D14: ANCORAMENTO TETTUCCIO SUPPORTO PARETE ZEROGRADI | E14: ANODIZZATO | F14: 8.7 | G14: 0.25 | H14: #N/A | I14: #N/A | J14: #N/A | K14: #N/A | L14: #N/A | M14: 0050 | N14: =+F14+G14 -> 8.95
A15: CPA | B15: 131375 | C15: T0002.417 | D15: BASAMENTO RINVIO ANGOLARE GAMBA TELESCOPICA ZEROGRADI | E15: GREZZO | F15: 18 | G15: resta gz | H15: #N/A | I15: #N/A | J15: #N/A | K15: #N/A | L15: #N/A | M15: 0000
A16: CPA | B16: 131377 | C16: T0002.426 | D16: DISCO FINECORSA GAMBA TELESCOPICA ZEROGRADI | E16: GREZZO | F16: 20 | G16: resta gz | H16: #N/A | I16: #N/A | J16: #N/A | K16: #N/A | L16: #N/A | M16: 0000
A17: CPA | B17: 131391 | C17: T0002.431 | D17: SUPPORTO FRANGITRATTA STATICO ZEROGRADI | E17: ANODIZZATO | F17: 9.32 | G17: non c'è a sistema | H17: #N/A | I17: #N/A | J17: #N/A | K17: #N/A | L17: #N/A | M17: 0050
A18: CPA | B18: 131403 | C18: T0002.455S | D18: TAPPO CASSONETTO VOLANT DX | E18: GREZZO | F18: 40 | G18: a commessa-non ho il costo | H18: #N/A | I18: #N/A | J18: #N/A | K18: #N/A | L18: #N/A | M18: 0000 + colori mag
A19: CPA | B19: 131404 | C19: T0002.455 | D19: TAPPO CASSONETTO VOLANT SX | E19: GREZZO | F19: 40 | G19: a commessa-non ho il costo | H19: #N/A | I19: #N/A | J19: #N/A | K19: #N/A | L19: #N/A | M19: 0000 + colori mag
A20: CPA | B20: 131405 | C20: T0002.456 | D20: PIN COLLEGAMENTO VOLANT LAVORATO | E20: ANODIZZATO | F20: 7.96 | G20: arriva già così | H20: #N/A | I20: #N/A | J20: #N/A | K20: #N/A | L20: #N/A | M20: 0050
A21: CPA | B21: 131406 | C21: T0002.457 | D21: SUPPORTO INTERMEDIO TETTUCCIO | E21: ANODIZZATO | F21: 11 | G21: arriva già così | H21: #N/A | I21: #N/A | J21: #N/A | K21: #N/A | L21: #N/A | M21: 0050
A22: 4C | B22: 111459 | C22: 3GE40.005 | D22: ROTELLA TERMINALE ANTI SCAVALLAMENTO ZEROGRADI | E22: P073 | F22: 0.36 | N22: =+F22 -> 0.36
A23: 4C | B23: 111460 | C23: T0002.137 | D23: AVVOLGICINGHIA CHIUSURA LATO FOLLE ZEROGRADI | E23: P073 | F23: 0.74 | N23: =+F23 -> 0.74
A24: 4C | B24: 111461 | C24: T0002.138 | D24: AVVOLGICINGHIA CHIUSURA LATO MOTORE ZEROGRADI | E24: P073 | F24: 0.51 | N24: =+F24 -> 0.51
A25: 4C | B25: 111462 | C25: T0002.136 | D25: AVVOLGICINGHIA CORONA ESTERNA ZEROGRADI | E25: P073 | F25: 1.08 | N25: =+F25 -> 1.08
A26: 4C | B26: 111463 | C26: T0002.135 | D26: AVVOLGICINGHIA SEMISUPPORTO PRINCIPALE ZEROGRADI | E26: P073 | F26: 0.53 | N26: =+F26 -> 0.53
A27: 4C | B27: 111464 | C27: T0002.115 | D27: GUSCIO SUPPORTO MOLLA LATO INTERNO ZEROGRADI | E27: P073 | F27: 0.68 | N27: =+F27 -> 0.68
A28: 4C | B28: 111465 | C28: T0002.141 | D28: PROTEGGI TELO FRANGITRATTA ZEROGRADI | E28: P134 | F28: 0.32 | N28: =+F28 -> 0.32
A29: 4C | B29: 111466 | C29: T0002.129 | D29: ROTELLA CARRELLO-RINVIO ZEROGRADI | E29: P073 | F29: 0.15 | N29: =+F29 -> 0.15
A30: 4C | B30: 111467 | C30: T0002.150 | D30: TAPPINO ANCORAGGIO GUIDA ZEROGRADI | E30: P134 | F30: 0.16 | N30: =+F30 -> 0.16
A31: 4C | B31: 111468 | C31: T0002.133 | D31: TAPPO CHIUSURA SUPERIORE GAMBA TELESCOPICA ZEROGRADI | E31: P134 | F31: 1.45 | N31: =+F31 -> 1.45
A32: 4C | B32: 111470 | C32: T0002.139 | D32: TRASCINATORE MOLLA ESTREMO Ø85 ZEROGRADI | E32: P073 | F32: 0.9 | N32: =+F32 -> 0.9
A33: 4C | B33: 111471 | C33: T0002.112 | D33: TRASCINATORE MOTORE MOLLA BASE ZEROGRADI | E33: P073 | F33: 0.76 | N33: =+F33 -> 0.76
... A36: 4C | B36: 111474 | C36: T0002.121 | D36: TRASCINATORE MOTORE MOLLA SOMFY P/ZEROGRADI | E36: P073 | F36: 0.87 | N36: =+F36 -> 0.87
A37: alubrass | B37: 101031 | C37: T0002.011 | D37: AGGANCIO CINGHIOLO GUIDA SENZA ZIP ZEROGRADI | E37: grezzo | F37: 0.76 | G37: 0.23 | N37: =+F37+G37 -> 0.99
A38: alubrass | B38: 101032 | C38: T0002.012S | D38: BLOCCA TELO FRONTALE DX - CON ZIP ZEROGRADI | E38: grezzo | F38: 1.704 | G38: 0.25 | N38: =+F38+G38 -> 1.954
A39: alubrass | B39: 101033 | C39: T0002.012 | D39: BLOCCA TELO FRONTALE SX - CON ZIP ZEROGRADI | E39: grezzo | F39: 1.704 | G39: 0.25 | N39: =+F39+G39 -> 1.954
A40: alubrass | B40: 101034 | C40: T0002.002S | D40: COVER TESTATA DX ZEROGRADI | E40: grezzo | F40: 2.824 | G40: 0.28 | N40: =+F40+G40 -> 3.104
A41: alubrass | B41: 101035 | C41: T0002.002 | D41: COVER TESTATA SX ZEROGRADI | E41: grezzo | F41: 2.824 | G41: 0.28 | N41: =+F41+G41 -> 3.104
A42: alubrass | B42: 101036 | C42: T0002.007 | D42: TAPPINO FINITURA GUIDA ZIP ZEROGRADI | E42: grezzo | F42: 0.788 | G42: 0.17 | N42: =+F42+G42 -> 0.958
...

Sheet Foglio1
A1: Codice | B1: Descrizione | C1: Implementazione distinta su smeup | D1: Rif kit | E1: Classe di riferimento | F1: Note sul posizionamento | G1: La massima misura di taglio | H1: Il massimo numero indicativo di pz (PER MODULO - non PER KIT) | I1: Codice nuovo? (ci sono codici NON nuovi??) | J1: La configurazione colore | K1: Chi assembla il componente all’interno del reparto | L1: Prefisso della sequenza | M1: Passa per le cassettine? | N1: reparto | O1: Classe di programmazione | P1: Crit configurazione | Q1: Le configurazioni | R1: La classe gestionale | S1: Parametro configurazione di partenza conto lavoro | T1: Cat. Logistica | U1: Ciclo alternativo sul 150 | V1: Centro di lavoro (solo per i profili) | W1: Fornitore | Y1: Inseribile | Z1: peso a metro matrice | AA1: codice ricavato | AB1: misura pz (mm) | AC1: pz per barra
A2: 010608 | B2: PR SUPPORTO CASSONETTO SUPERIORE ZEROGRADI - WGB | D2: no | E2: 01 - Estrusi metallici | F2: DA LAVORARE - non in distinta - serve per ricavare 090364 | H2: 1 | I2: si | J2: Fissa | P2: 004 | Q2: 000006000 | R2: PRALU | W2: anodall extrusion | Y2: Inserito in Smeup o comunicato al CED o deciso | Z2: 1.62 | AA2: 090364 | AB2: 60 | AC2: =6000/(AB2+5) -> 92.307692 | AD2: =+A2 -> 010608 | AE2: =+Z2 -> 1.62
A3: 010609 | B3: PR GUIDA C-ZIP ZEROGRADI - WGB | D3: no | E3: 01 - Estrusi metallici | F3: IN VISTA | G3: 5770 | H3: 2 | I3: si | J3: Struttura | K3: Reparto | N3: quante con e senza zip? Tot 100 o tot 200? | P3: 004 | Q3: 000006000 | R3: PRALU | W3: anodall extrusion | Y3: Da inserire in smeup | Z3: 2.377 | AD3: =+A3 -> 010609 | AE3: =+Z3 -> 2.377
A4: 010611 | B4: PR GUIDA SENZA ZIP ZEROGRADI - WGB | D4: no | E4: 01 - Estrusi metallici | F4: IN VISTA | G4: 5770 | H4: 2 | I4: si | J4: Struttura | K4: Reparto | N4: quante con e senza zip? Tot 100 o tot 200? | P4: 004 | Q4: 000006000 | R4: PRALU | W4: anodall extrusion | Z4: 1.722 | AD4: =+A4 -> 010611 | AE4: =+Z4 -> 1.722
A5: 010616 | B5: PR TETTUCCIO ROTABILE ZEROGRADI - WGB | D5: no | E5: 01 - Estrusi metallici | F5: OPTIONAL - IN VISTA | G5: 6000 | H5: 1 | I5: si | J5: Struttura | K5: Cliente | N5: minimo 100 barre, ok? | P5: 004 | Q5: 000006050 | R5: PRALU | W5: anodall extrusion | Z5: 0.725 | AD5: =+A5 -> 010616 | AE5: =+Z5 -> 0.725
A6: 010617 | B6: PR SUPPORTO GUIDE AD INCASTRO ZEROGRADI - WGB | D6: no | E6: 01 - Estrusi metallici | F6: DA LAVORARE - non in distinta - serve per ricavare 090361 | G6: 50 | H6: 16 | I6: si | J6: Struttura | P6: 004 | Q6: 000006000 | R6: PRALU | W6: anodall extrusion | Z6: 0.9 | AA6: 090361 | AB6: 45 | AC6: 120 | AD6: =+A6 -> 010617 | AE6: =+Z6 -> 0.9
A7: 010618 | B7: PR QUADRO 70X70 4 OGIVE | D7: no | E7: 01 - Estrusi metallici | F7: OPTIONAL - IN VISTA - frangitratta (sempre se L o S>5m o a richiesta maz 2pz per tenda) o gamba telescopica o singola (a richiesta max 2pz) | G7: Frangitratta 5946 - gambe<2800 | H7: 1 | I7: si | J7: Struttura | K7: Reparto | N7: 30 intanto? Vedi utilizzo | P7: 004 | Q7: 000006000 | R7: PRALU | W7: anodall extrusion | Z7: 1.791 | AD7: =+A7 -> 010618 | AE7: =+Z7 -> 1.791
A8: 010619 | B8: PR SUPPORTO TETTUCCIO ZEROGRADI - WGB | D8: no | E8: 01 - Estrusi metallici | F8: DA LAVORARE - serve per ricavare 090363 | G8: 50 | H8: 4 | I8: si | J8: Fissa | P8: 004 | Q8: 000006000 | R8: PRALU | W8: anodall extrusion | Z8: 0.891 | AA8: 090363 | AB8: 32 | AC8: =6000/(AB8+5) -> 162.16216 | AD8: =+A8 -> 010619 | AE8: =+Z8 -> 0.891
A9: 010627 | B9: PR CASSONETTO MONOBLOCCO PORTANTE ZEROGRADI - WGB | D9: no | E9: 01 - Estrusi metallici | F9: IN VISTA | G9: 5910 | H9: 1 | I9: si | J9: Struttura | K9: Reparto | P9: 004 | Q9: 000006000 | R9: PRALU | W9: anodall extrusion | Z9: 4.91 | AD9: =+A9 -> 010627 | AE9: =+Z9 -> 4.91
A10: 010628 | B10: PR CHIUSURA CASSONETTO PORTA LED ZEROGRADI - WGB | D10: no | E10: 01 - Estrusi metallici | F10: IN VISTA | G10: 5910 | H10: 1 | I10: si | J10: Struttura | K10: Reparto | P10: 004 | Q10: 000006000 | R10: PRALU | W10: anodall extrusion | Z10: 0.472 | AD10: =+A10 -> 010628 | AE10: =+Z10 -> 0.472
A11: 010629 | B11: PR AGGANCIO CASSONETTO PARETE ZEROGRADI - WGB | D11: no | E11: 01 - Estrusi metallici | F11: DA LAVORARE - serve per ricavare 090359 | G11: 100 | H11: 4 | I11: si | J11: Fissa | P11: 003 | Q11: 000006000 | R11: PRALU | W11: anodall extrusion | Z11: 1.145 | AA11: 090359 | AB11: 90 | AC11: =6000/(AB11+5) -> 63.157895 | AD11: =+A11 -> 010629 | AE11: =+Z11 -> 1.145
A12: 010630 | B12: PR MONOOGIVA ANCORABILE ZEROGRADI - WGB | D12: no | E12: 01 - Estrusi metallici | F12: SI VEDE SOLO DALL'ALTO | G12: 5830 | H12: 1 | I12: si | J12: Fissa | K12: Reparto | N12: minimo 100 barre | P12: 004 | Q12: 000006000 | R12: PRALU | W12: anodall extrusion | Z12: 0.344 | AD12: =+A12 -> 010630 | AE12: =+Z12 -> 0.344
A13: 010631 | B13: PR PROLUNGA GUARNIZIONE ROMPIACQUA ZEROGRADI - WGB | D13: no | E13: 01 - Estrusi metallici | F13: IN VISTA | G13: 5870 | H13: 1 | I13: si | J13: Struttura | K13: Reparto | P13: 004 | Q13: 000006000 | R13: PRALU | W13: anodall extrusion | Z13: 0.386 | AD13: =+A13 -> 010631 | AE13: =+Z13 -> 0.386
A14: 010633 | B14: PR COVER CASSONETTO VOLANT D49 ZEROGRADI - WGB | D14: no | E14: 01 - Estrusi metallici | F14: OPTIONAL - IN VISTA | G14: 5800 | H14: 1 | I14: si | J14: Struttura | K14: Reparto | P14: 004 | Q14: 000006000 | R14: PRALU | W14: anodall extrusion | Z14: 1.386 | AD14: =+A14 -> 010633 | AE14: =+Z14 -> 1.386
A15: 010634 | B15: PR FRONTALE AGGANCIABILE ZEROGRADI - WGB | D15: no | E15: 01 - Estrusi metallici | F15: IN VISTA | G15: 5830 | H15: 1 | I15: si | J15: Struttura | K15: Reparto | P15: 004 | Q15: 000006000 | R15: PRALU | W15: anodall extrusion | Z15: 3.055 | AD15: =+A15 -> 010634 | AE15: =+Z15 -> 3.055
A16: 010635 | B16: PR REGGISTRIP ZEROGRADI - WGB | D16: no | E16: 01 - Estrusi metallici | F16: NON IN VISTA | G16: 5770 | H16: 1 | I16: si | J16: Fissa | K16: Reparto | P16: 004 | Q16: 005106000 | R16: PRALU | W16: anodall extrusion | Z16: 0.156 | AD16: =+A16 -> 010635 | AE16: =+Z16 -> 0.156
A17: 010636 | B17: PR CASSONETTO PORTANTE VOLANT D49 ZEROGRADI - WGB | D17: no | E17: 01 - Estrusi metallici | F17: OPTIONAL - IN VISTA | G17: 5800 | H17: 1 | I17: si | J17: Struttura | K17: Reparto | P17: 004 | Q17: 000006000 | R17: PRALU | W17: anodall extrusion | Z17: 1.342 | AD17: =+A17 -> 010636 | AE17: =+Z17 -> 1.342
A18: 010637 | B18: PR ANTISOLLEVAMENTO SUPP PARETE ZEROGRADI - WGB | D18: no | E18: 01 - Estrusi metallici | F18: DA LAVORARE - serve per ricavare 090362 | G18: 100 | H18: 4 | I18: si | J18: Fissa | P18: 004 | Q18: 000006000 | R18: PRALU | W18: anodall extrusion | Z18: 0.559 | AA18: 090362 | AB18: 90 | AC18: =6000/(AB18+5) -> 63.157895 | AD18: =+A18 -> 010637 | AE18: =+Z18 -> 0.559
A19: 010638 | B19: PR CASSONETTO INSERIBILE SUPERIORE ZEROGRADI - WGB | D19: no | E19: 01 - Estrusi metallici | F19: IN VISTA | G19: 5910 | H19: 1 | I19: si | J19: Struttura | K19: Reparto | P19: 004 | Q19: 000006000 | R19: PRALU | W19: anodall extrusion | Z19: 1.669 | AD19: =+A19 -> 010638 | AE19: =+Z19 -> 1.669
A20: 010639 | B20: PR SUPPORTO PARETE ANCORABILE ZEROGRADI - WGB | D20: no | E20: 01 - Estrusi metallici | F20: DA LAVORARE - serve per ricavare 090365 | G20: 200 | H20: 4 | I20: si | J20: Fissa | P20: 004 | Q20: 000006000 | R20: PRALU | W20: anodall extrusion | Z20: 5.338 | AA20: 090365 | AB20: 180 | AC20: =6000/(AB20+5) -> 32.432432 | AD20: =+A20 -> 010639 | AE20: =+Z20 -> 5.338
A21: 220045 | B21: CINGHIA DI TENSIONAMENTO 12X1 MONOASOLA | D21: no | E21: 22 - Funi-Cinghie | F21: // | H21: 2 | I21: si | J21: Fissa | K21: Reparto | N21: 100 | P21: 004 | Q21: da verificare se le altre cinghie arrivano con configurazioni; arriva nera, leggermente in vista | W21: erreti | AD21: =+A21 -> 220045 | AE21: =+Z21 -> 0
A22: 146419 | B22: CHIAVETTA DI TRASMISSIONE 4X4X25 | D22: 272358 | E22: 14 - Elementi di fissaggio | F22: // | H22: 1 | I22: si | J22: No Configurazione | K22: In kit | N22: 200 | P22: - | W22: b&m | AD22: =+A22 -> 146419 | AE22: =+Z22 -> 0
A23: 260053 | B23: MANOVELLA GAMBA TELESCOPICA ZEROGRADI | D23: no | E23: 26 - Accessorio/Altro materiale | F23: // | H23: 1 | I23: si | J23: Fissa | K23: Reparto | N23: 100 | P23: 003 | Q23: P073 | W23: Fastpoint | AD23: =+A23 -> 260053 | AE23: =+Z23 -> 0
A24: 111458 | B24: PASSACAVO MORBIDO 14X8X10 SP3 ZEROGRADI | D24: 272343 | E24: 11 - Stampati plastica | F24: // | H24: 2 | I24: si | J24: Fissa | K24: Reparto | N24: 200 | P24: 003 | Q24: P073 | W24: Fastpoint | AD24: =+A24 -> 111458 | AE24: =+Z24 -> 0
A25: 320111 | B25: PIEDINO ADESIVO PARACOLPI 12.7x3.5 | D25: no | E25: 32 - Commerciali | F25: // | H25: 5 | I25: si | J25: Fissa | K25: Reparto | N25: 100 | P25: - | Q25: P134 | W25: Fastpoint | AD25: =+A25 -> 320111 | AE25: =+Z25 -> 0
A26: 146428 | B26: VITE TRILOBATA TSPEI M5x12 INOX | D26: no | E26: 14 - Elementi di fissaggio | F26: // | H26: 1 | I26: si | J26: No Configurazione | K26: Reparto | N26: 100 | P26: - | W26: b&m | AD26: =+A26 -> 146428 | AE26: =+Z26 -> 0
A27: 146429 | B27: VITE TRILOBATA TSPEI M5x8 INOX | D27: no | E27: 14 - Elementi di fissaggio | F27: // | H27: 8 | I27: si | J27: No Configurazione | K27: Reparto | N27: 100 | P27: - | W27: b&m | AD27: =+A27 -> 146429 | AE27: =+Z27 -> 0
A28: 146210 | B28: ANELLO ELASTICO ALBERO D14 INOX | D28: 272358 | E28: 14 - Elementi di fissaggio | F28: // | H28: 1 | I28: si | J28: No Configurazione | K28: In kit | N28: 200 | P28: - | W28: b&m | AD28: =+A28 -> 146210 | AE28: =+Z28 -> 0
A29: 146421 | B29: GRANO EI PUNTA CONICA M8x20 INOX | D29: 272357 | E29: 14 - Elementi di fissaggio | F29: // | H29: 16 | I29: si | J29: No Configurazione | K29: In kit | N29: 200 | P29: - | W29: b&m | AD29: =+A29 -> 146421 | AE29: =+Z29 -> 0
A30: 146426 | B30: VITE TCEI M5x50 INOX | D30: 272347 + 272359 | E30: 14 - Elementi di fissaggio | F30: // | H30: 4 | I30: si | J30: No Configurazione | K30: In kit | N30: 200 | P30: - | W30: b&m | AD30: =+A30 -> 146426 | AE30: =+Z30 -> 0
A31: 146425 | B31: VITE TCEI M10x50 INOX | D31: no | E31: 14 - Elementi di fissaggio | F31: // | H31: 2 | I31: si | J31: No Configurazione | K31: Reparto | N31: 100 | P31: - | W31: b&m | AD31: =+A31 -> 146425 | AE31: =+Z31 -> 0
A32: 146430 | B32: VITE TSPEI M4x12 INOX | D32: 272343 + 272346 + 272349 | E32: 14 - Elementi di fissaggio | F32: // | H32: 14 | I32: si | J32: No Configurazione | K32: In kit | N32: 200 | P32: - | W32: b&m | AD32: =+A32 -> 146430 | AE32: =+Z32 -> 0
A33: 146431 | B33: VITE TSPEI M5x20 INOX | D33: 272345+272348+272355+272356 | E33: 14 - Elementi di fissaggio | F33: // | H33: 16 | I33: si | J33: No Configurazione | K33: In kit | N33: 200 | P33: - | W33: b&m | AD33: =+A33 -> 146431 | AE33: =+Z33 -> 0
A34: 146422 | B34: SPINA CILINDRICA 4x8 INOX | D34: 272343+272400 | E34: 14 - Elementi di fissaggio | F34: // | H34: 2 | I34: si | J34: No Configurazione | K34: In kit | N34: 200 | P34: - | W34: b&m | AD34: =+A34 -> 146422 | AE34: =+Z34 -> 0
A35: 160160 | B35: MOLLA DI TENSIONAMENTO RULLO SX ZEROGRADI | D35: 272345+272355 | E35: 16 - Molle catene | F35: // | H35: 2 | I35: si | J35: No Configurazione | K35: In kit | N35: 200 | P35: - | W35: Mollificio Rizzato | AD35: =+A35 -> 160160 | AE35: =+Z35 -> 0
A36: 160159 | B36: MOLLA DI TENSIONAMENTO RULLO DX ZEROGRADI | D36: 272348+272356 | E36: 16 - Molle catene | F36: // | H36: 2 | I36: si | J36: No Configurazione | K36: In kit | N36: 200 | P36: - | W36: Mollificio Rizzato | AD36: =+A36 -> 160159 | AE36: =+Z36 -> 0
A37: 160161 | B37: MOLLA GANCIO FRONTALE ZEROGRADI | D37: 272343 | E37: 16 - Molle catene | F37: // | H37: 2 | I37: si | J37: No Configurazione | K37: In kit | N37: 200 | P37: - | W37: Mollificio Rizzato | AD37: =+A37 -> 160161 | AE37: =+Z37 -> 0
A38: 122233 | B38: CONTROTAPPO TESTATA VOLANT DX | D38: 272400 | E38: 12 - Tagliati laser e inseparabili | F38: OPTIONAL - IN VISTA | H38: 1 | I38: si | J38: Fissa | K38: In kit | N38: 200 | P38: 003 | Q38: 0187 | W38: tovotec | AD38: =+A38 -> 122233 | AE38: =+Z38 -> 0
A39: 122234 | B39: CONTROTAPPO TESTATA VOLANT SX | D39: 272400 | E39: 12 - Tagliati laser e inseparabili | F39: OPTIONAL - IN VISTA | H39: 1 | I39: si | J39: Fissa | K39: In kit | N39: 200 | P39: 003 | Q39: 0187 | W39: tovotec | AD39: =+A39 -> 122234 | AE39: =+Z39 -> 0
A40: 131373 | B40: VITE TRAPEZOIDALE TR20X4 - L 565 | D40: 272358 | E40: 13 - Lavorati Meccanici | F40: OPTIONAL - NON IN VISTA | H40: 1 | I40: si | J40: No Configurazione | K40: In kit | N40: 200 | P40: - | W40: megaveneto | AD40: =+A40 -> 131373 | AE40: =+Z40 -> 0
...
